<?xml version="1.0"?>
<robot name="pendulum">
  <link name="world"/>

  <joint name="fixed_base" type="fixed">
    <parent link="world"/>
    <child link="base_link"/>
    <origin xyz="0 0 2.0" rpy="0 0 0"/>
  </joint>

  <link name="base_link">
    <visual>
      <geometry>
        <box size="0.2 0.2 0.2"/>
      </geometry>
      <material name="grey">
        <color rgba="0.2 0.2 0.2 1.0"/>
      </material>
    </visual>
    <collision>
      <geometry>
        <box size="0.2 0.2 0.2"/>
      </geometry>
    </collision>
    <inertial>
      <mass value="100.0"/>
      <inertia ixx="1.0" ixy="0.0" ixz="0.0" iyy="1.0" iyz="0.0" izz="1.0"/>
    </inertial>
  </link>

  <joint name="revolute_joint" type="revolute">
    <parent link="base_link"/>
    <child link="pendulum_link"/>
    <origin xyz="0 0 0" rpy="0 0 0"/>
    <axis xyz="0 1 0"/>
    <limit lower="-3.14159" upper="3.14159" effort="50.0" velocity="20.0"/>
    <dynamics damping="0.0" friction="0.0"/>
  </joint>

  <link name="pendulum_link">
    <visual>
      <origin xyz="0 0 -0.5" rpy="0 0 0"/>
      <geometry>
        <cylinder radius="0.05" length="1.0"/>
      </geometry>
      <material name="red">
        <color rgba="0.8 0.1 0.1 1.0"/>
      </material>
    </visual>
    <collision>
      <origin xyz="0 0 -0.5" rpy="0 0 0"/>
      <geometry>
        <cylinder radius="0.05" length="1.0"/>
      </geometry>
    </collision>
    <inertial>
      <origin xyz="0 0 -0.5" rpy="0 0 0"/>
      <mass value="1.0"/>
      <inertia ixx="0.08" ixy="0.0" ixz="0.0" iyy="0.08" iyz="0.0" izz="0.001"/>
    </inertial>
  </link>
</robot>
